Workbook

Sheet LagTime
A1: subbasin | B1: distance | C1: Elev_1 | D1: Slp | E1: LagTimeTemez_min | F1: LagTimeTKirpich_min | G1: LagTimeMed
A2: W1 | B2: 0 | C2: 151.19298
A3: W1 | B3: 6842.7075 | C3: 1071.6447 | D3: =IF((C3-C2)/B3>0, (C3-C2)/B3,0.001) -> 0.13451571 | E3: =(0.3*((LagTime!B3/1000)/LagTime!D3^0.25)^0.76)*60 -> 113.65247 | F3: =(0.00013*B3^0.77/D3^0.385)*60 -> 15.158022 | G3: =AVERAGE(E3:F3) -> 64.405248
A4: W10 | B4: 0 | C4: 83.987961
A5: W10 | B5: 5185.7635 | C5: 86.233955 | D5: =IF((C5-C4)/B5>0, (C5-C4)/B5,0.001) -> 0.00043310779 | E5: =(0.3*((LagTime!B5/1000)/LagTime!D5^0.25)^0.76)*60 -> 273.89047 | F5: =(0.00013*B5^0.77/D5^0.385)*60 -> 111.53494 | G5: =AVERAGE(E5:F5) -> 192.7127
A6: W11 | B6: 0 | C6: 135.71277
A7: W11 | B7: 2897.372 | C7: 180.31683 | D7: =IF((C7-C6)/B7>0, (C7-C6)/B7,0.001) -> 0.015394663 | E7: =(0.3*((LagTime!B7/1000)/LagTime!D7^0.25)^0.76)*60 -> 89.288476 | F7: =(0.00013*B7^0.77/D7^0.385)*60 -> 18.017742 | G7: =AVERAGE(E7:F7) -> 53.653109
A8: W12 | B8: 0 | C8: 93.398422
A9: W12 | B9: 4501.1422 | C9: 109.237 | D9: =IF((C9-C8)/B9>0, (C9-C8)/B9,0.001) -> 0.0035187907 | E9: =(0.3*((LagTime!B9/1000)/LagTime!D9^0.25)^0.76)*60 -> 165.18972 | F9: =(0.00013*B9^0.77/D9^0.385)*60 -> 44.646933 | G9: =AVERAGE(E9:F9) -> 104.91833
A10: W13 | B10: 0 | C10: 82.905014
A11: W13 | B11: 10111.704 | C11: 133.22206 | D11: =IF((C11-C10)/B11>0, (C11-C10)/B11,0.001) -> 0.0049761193 | E11: =(0.3*((LagTime!B11/1000)/LagTime!D11^0.25)^0.76)*60 -> 286.10785 | F11: =(0.00013*B11^0.77/D11^0.385)*60 -> 72.862894 | G11: =AVERAGE(E11:F11) -> 179.48537
A12: W14 | B12: 0 | C12: 71.477234
A13: W14 | B13: 10365.509 | C13: 85.723694 | D13: =IF((C13-C12)/B13>0, (C13-C12)/B13,0.001) -> 0.0013744101 | E13: =(0.3*((LagTime!B13/1000)/LagTime!D13^0.25)^0.76)*60 -> 372.28821 | F13: =(0.00013*B13^0.77/D13^0.385)*60 -> 121.8778 | G13: =AVERAGE(E13:F13) -> 247.083
A14: W15 | B14: 0 | C14: 101.33729
A15: W15 | B15: 6167.4491 | C15: 146.51241 | D15: =IF((C15-C14)/B15>0, (C15-C14)/B15,0.001) -> 0.0073247654 | E15: =(0.3*((LagTime!B15/1000)/LagTime!D15^0.25)^0.76)*60 -> 182.57526 | F15: =(0.00013*B15^0.77/D15^0.385)*60 -> 42.907214 | G15: =AVERAGE(E15:F15) -> 112.74124
A16: W16 | B16: 0 | C16: 81.172806
A17: W16 | B17: 6826.3679 | C17: 104.88996 | D17: =IF((C17-C16)/B17>0, (C17-C16)/B17,0.001) -> 0.0034743448 | E17: =(0.3*((LagTime!B17/1000)/LagTime!D17^0.25)^0.76)*60 -> 227.24316 | F17: =(0.00013*B17^0.77/D17^0.385)*60 -> 61.827913 | G17: =AVERAGE(E17:F17) -> 144.53554
A18: W17 | B18: 0 | C18: 95.631912
A19: W17 | B19: 8738.3666 | C19: 127.12714 | D19: =IF((C19-C18)/B19>0, (C19-C18)/B19,0.001) -> 0.0036042461 | E19: =(0.3*((LagTime!B19/1000)/LagTime!D19^0.25)^0.76)*60 -> 272.24804 | F19: =(0.00013*B19^0.77/D19^0.385)*60 -> 73.726284 | G19: =AVERAGE(E19:F19) -> 172.98716
A20: W18 | B20: 0 | C20: 80.321762
A21: W18 | B21: 1098.6837 | C21: 85.43222 | D21: =IF((C21-C20)/B21>0, (C21-C20)/B21,0.001) -> 0.0046514375 | E21: =(0.3*((LagTime!B21/1000)/LagTime!D21^0.25)^0.76)*60 -> 53.640666 | F21: =(0.00013*B21^0.77/D21^0.385)*60 -> 13.537719 | G21: =AVERAGE(E21:F21) -> 33.589192
A22: W19 | B22: 0 | C22: 82.256157
A23: W19 | B23: 4678.968 | C23: 86.696686 | D23: =IF((C23-C22)/B23>0, (C23-C22)/B23,0.001) -> 0.00094904022 | E23: =(0.3*((LagTime!B23/1000)/LagTime!D23^0.25)^0.76)*60 -> 218.22399 | F23: =(0.00013*B23^0.77/D23^0.385)*60 -> 76.182564 | G23: =AVERAGE(E23:F23) -> 147.20328
A24: W2 | B24: 0 | C24: 105.5303
A25: W2 | B25: 14172.495 | C25: 1075.381 | D25: =IF((C25-C24)/B25>0, (C25-C24)/B25,0.001) -> 0.068431895 | E25: =(0.3*((LagTime!B25/1000)/LagTime!D25^0.25)^0.76)*60 -> 224.73596 | F25: =(0.00013*B25^0.77/D25^0.385)*60 -> 34.445597 | G25: =AVERAGE(E25:F25) -> 129.59078
A26: W20 | B26: 0 | C26: 80.576576
A27: W20 | B27: 2533.3472 | C27: 85.43222 | D27: =IF((C27-C26)/B27>0, (C27-C26)/B27,0.001) -> 0.0019166912 | E27: =(0.3*((LagTime!B27/1000)/LagTime!D27^0.25)^0.76)*60 -> 119.78311 | F27: =(0.00013*B27^0.77/D27^0.385)*60 -> 36.237393 | G27: =AVERAGE(E27:F27) -> 78.01025
A28: W21 | B28: 0 | C28: 82.905014
A29: W21 | B29: 3307.9607 | C29: 90.092537 | D29: =IF((C29-C28)/B29>0, (C29-C28)/B29,0.001) -> 0.0021727957 | E29: =(0.3*((LagTime!B29/1000)/LagTime!D29^0.25)^0.76)*60 -> 143.25335 | F29: =(0.00013*B29^0.77/D29^0.385)*60 -> 42.403704 | G29: =AVERAGE(E29:F29) -> 92.828525
A30: W22 | B30: 0 | C30: 128.72072
A31: W22 | B31: 5738.9712 | C31: 661.6106 | D31: =IF((C31-C30)/B31>0, (C31-C30)/B31,0.001) -> 0.0928546 | E31: =(0.3*((LagTime!B31/1000)/LagTime!D31^0.25)^0.76)*60 -> 106.68509 | F31: =(0.00013*B31^0.77/D31^0.385)*60 -> 15.268364 | G31: =AVERAGE(E31:F31) -> 60.976727
A32: W23 | B32: 0 | C32: 105.5303
A33: W23 | B33: 7498.7417 | C33: 705.22107 | D33: =IF((C33-C32)/B33>0, (C33-C32)/B33,0.001) -> 0.079972186 | E33: =(0.3*((LagTime!B33/1000)/LagTime!D33^0.25)^0.76)*60 -> 134.49473 | F33: =(0.00013*B33^0.77/D33^0.385)*60 -> 19.870288 | G33: =AVERAGE(E33:F33) -> 77.182511
A34: W24 | B34: 0 | C34: 151.19298
A35: W24 | B35: 8009.5091 | C35: 1206.3545 | D35: =IF((C35-C34)/B35>0, (C35-C34)/B35,0.001) -> 0.1317386 | E35: =(0.3*((LagTime!B35/1000)/LagTime!D35^0.25)^0.76)*60 -> 128.60786 | F35: =(0.00013*B35^0.77/D35^0.385)*60 -> 17.249703 | G35: =AVERAGE(E35:F35) -> 72.928782
A36: W25 | B36: 0 | C36: 94.568062
A37: W25 | B37: 6544.2754 | C37: 142.64549 | D37: =IF((C37-C36)/B37>0, (C37-C36)/B37,0.001) -> 0.0073464865 | E37: =(0.3*((LagTime!B37/1000)/LagTime!D37^0.25)^0.76)*60 -> 190.88515 | F37: =(0.00013*B37^0.77/D37^0.385)*60 -> 44.860832 | G37: =AVERAGE(E37:F37) -> 117.87299
A38: W26 | B38: 0 | C38: 80.417152
A39: W26 | B39: 17659.194 | C39: 388.12628 | D39: =IF((C39-C38)/B39>0, (C39-C38)/B39,0.001) -> 0.017424868 | E39: =(0.3*((LagTime!B39/1000)/LagTime!D39^0.25)^0.76)*60 -> 344.46743 | F39: =(0.00013*B39^0.77/D39^0.385)*60 -> 69.089479 | G39: =AVERAGE(E39:F39) -> 206.77845
A40: W27 | B40: 0 | C40: 80.097534
...

Sheet Refs
B2: References
B3: http://lab-hidrologia.uca.es/metodo_temez_modificado/index.php
