Workbook

Sheet EstacionVirtual
G1: v.20211129
B3: Estaciones virtuales
B4: Tipo | C4: IdEstacion | D4: Nombre | E4: Latitud, ° | F4: Longitud, ° | G4: Altitud, m
B5: Estación virtual | C5: Virtual1 | D5: Virtual 1 | E5: 10.064161 | F5: -72.937769 | G5: 2871
C6: Virtual2 | D6: Virtual 2 | E6: 9.739112 | F6: -72.944279 | G6: 1323
C7: Virtual3 | D7: Virtual 3 | E7: 9.55008 | F7: -73.027958 | G7: 595
C8: Virtual4 | D8: Virtual 4 | E8: 9.395879 | F8: -73.196423 | G8: 2467
B9: Latitud y longitud en grados decimales proyectados en sistema WGS 1984. | F9: Zonal Virtual >> | G9: =AVERAGE(G5:G8) -> 1814

Sheet Metodo
B2: Métodos para extensión espacial de datos de precipitación
B3: Requerimientos y aplicabilidad vs. Método según el tipo de datos disponibles | D3: =Metodo1!B2 -> Método 1: estimación de la precipitación máxima en estaciones virtuales a partir del valor inverso de la distancia | E3: =Metodo2!B2 -> Método 2: estimación de la precipitación máxima en estaciones virtuales a partir de la relación entre la precipitación máxima, la precipitación media y el valor inverso de la distancia | F3: =Metodo3!B2 -> Método 3: estimación de la precipitación máxima en estaciones virtuales a partir de la relación entre la precipitación máxima, la precipitación media, la altitud y el valor inverso de la distancia | G3: =Metodo4!B2 -> Método 4: estimación de la precipitación máxima en estaciones virtuales a partir de la relación entre la precipitación máxima, la precipitación media, el logaritmo de la altitud y el valor inverso de la distancia
B4: Función | C4: Método de cálculo
B7: Requerimiento | C7: Precipitación máxima media anual en estaciones reales | D7: 1 | E7: 1 | F7: 1 | G7: 1
C8: Precipitación total media anual en estaciones reales y virtuales | D8: 0 | E8: 1 | F8: 1 | G8: 1
C9: Distancia entre estaciones reales y virtuales (Latitud y Longitud) | D9: 1 | E9: 1 | F9: 1 | G9: 1
C10: Altitud en estaciones reales y virtuales | D10: 0 | E10: 0 | F10: 1 | G10: 1
B12: Aplicabilidad | C12: El centro geográfico de la precipitación máxima ocurre dentro del área espacial de las estaciones reales | D12: 1 | E12: 0 | F12: 0 | G12: 0
C13: El centro geográfico de la precipitación máxima ocurre fuera del área espacial de las estaciones reales | D13: 1 | E13: 1 | F13: 1 | G13: 1
C14: Precipitación total en estaciones reales y virtuales tiene alta desviación estándar | D14: 1 | E14: 0 | F14: 0 | G14: 0
C15: Precipitación total en estaciones reales y virtuales tiene desviación estándar menor al 10% de la media de los valores | D15: 1 | E15: 1 | F15: 1 | G15: 1
C16: Estaciones virtuales se localizan dentro de la cuenca de estudio | D16: 1 | E16: 1 | F16: 1 | G16: 1
C17: Estaciones virtuales se localizan fuera de la cuenca de estudio | D17: 1 | E17: 0 | F17: 0 | G17: 0
C18: Altitud en estaciones reales y virtuales tiene baja desviación estándar menor al 10% de la media de los valores | D18: 1 | E18: 0 | F18: 1 | G18: 1
C19: Régimen hidrológico de la cuenca de estudio es similar al de la cuenca donde se ubican las estaciones virtuales | D19: 1 | E19: 1 | F19: 1 | G19: 1
C20: Régimen hidrológico de la cuenca de estudio es diferente al de la cuenca donde se ubican las estaciones virtuales | D20: 1 | E20: 0 | F20: 0 | G20: 0

Sheet Metodo1
B2: Método 1: estimación de la precipitación máxima en estaciones virtuales a partir del valor inverso de la distancia
B3: (Máximos obtenidos del análisis realizado previamente y almacenado en el archivo ..\HIDG\Tablas\PMax24h_v0.xls)
B5: A. Estaciones | F5: Zonal Real >> | G5: =AVERAGE(G7:G32) -> 136.92308 | H5: =AVERAGE(H7:H32) -> 97.615969 | I5: =AVERAGE(I7:I32) -> 33.053471
B6: Tipo | C6: IdEstación | D6: Nombre | E6: Latitud, ° | F6: Longitud, ° | G6: Altitud, m | H6: PMax24h, mm | I6: PMaxDesvStd, mm
A7: 1 | B7: Estación real | C7: 25020230 | D7: JAGUA LA [25020230] | E7: 9.5621667 | F7: -73.339472 | G7: 135 | H7: 105.8007 | I7: 38.727465
A8: 2 | C8: 25020240 | D8: CANAL EL [25020240] | E8: 9.4104722 | F8: -73.890417 | G8: 55 | H8: 104.89744 | I8: 27.984765
A9: 3 | C9: 25020250 | D9: CURUMANI [25020250] | E9: 9.1971944 | F9: -73.541944 | G9: 61 | H9: 108.5942 | I9: 27.311794
A10: 4 | C10: 25020260 | D10: RINCONHONDO [25020260] | E10: 9.3970278 | F10: -73.488028 | G10: 64 | H10: 106.89744 | I10: 31.885317
A11: 5 | C11: 25020280 | D11: LOMA LA [25020280] | E11: 9.6065278 | F11: -73.611972 | G11: 42 | H11: 109.06667 | I11: 36.410592
A12: 6 | C12: 25020690 | D12: POPONTE [25020690] | E12: 9.4232778 | F12: -73.410944 | G12: 91 | H12: 97.25641 | I12: 27.481781
A13: 7 | C13: 25020920 | D13: PRIMAVERA LA [25020920] | E13: 9.2166667 | F13: -73.416667 | G13: 1268 | H13: 100.90278 | I13: 48.729675
A14: 8 | C14: 25021240 | D14: CHIMICHAGUA [25021240] | E14: 9.2600833 | F14: -73.809861 | G14: 33 | H14: 106.33158 | I14: 22.082696
A15: 9 | C15: 25021650 | D15: YUCAL EL [25021650] | E15: 9.5573889 | F15: -73.876194 | G15: 43 | H15: 101.80571 | I15: 28.160192
A16: 10 | C16: 25025250 | D16: CHIRIGUANA [25025250] | E16: 9.3610278 | F16: -73.593389 | G16: 32 | H16: 108.04098 | I16: 39.029992
A17: 11 | C17: 28010070 | D17: VILLA MARLENE [28010070] | E17: 10.1855 | F17: -73.467111 | G17: 78 | H17: 72.694872 | I17: 38.58688
A18: 12 | C18: 28020080 | D18: PLAYAS LAS HACIENDA [28020080] | E18: 9.8480833 | F18: -73.462194 | G18: 58 | H18: 100.62051 | I18: 43.153649
A19: 13 | C19: 28020150 | D19: ESPERANZA LA HACIENDA [28020150] | E19: 10.029972 | F19: -73.668833 | G19: 83 | H19: 72.206197 | I19: 35.663791
... A32: 26 | C32: 28040350 | D32: PASO EL [28040350] | E32: 9.6569722 | F32: -73.743694 | G32: 34 | H32: 112.25768 | I32: 74.019251
A33: 27 | B33: Estación virtual | C33: Virtual1 | D33: Virtual 1 | E33: 10.064161 | F33: -72.937769 | G33: 2871 | H33: =$M$42 -> 95.90906 | I33: =P42 -> 31.791561
A34: 28 | C34: Virtual2 | D34: Virtual 2 | E34: 9.739112 | F34: -72.944279 | G34: 1323 | H34: =$M$68 -> 96.581282 | I34: =P68 -> 28.268044
A35: 29 | C35: Virtual3 | D35: Virtual 3 | E35: 9.55008 | F35: -73.027958 | G35: 595 | H35: =$M$94 -> 96.555343 | I35: =P94 -> 30.127197
A36: 30 | C36: Virtual4 | D36: Virtual 4 | E36: 9.395879 | F36: -73.196423 | G36: 2467 | H36: =$M$120 -> 101.23163 | I36: =P120 -> 33.567577
F37: Zonal Virtual >> | G37: =AVERAGE(G33:G36) -> 1814 | H37: =AVERAGE(H33:H36) -> 97.569329 | I37: =AVERAGE(I33:I36) -> 30.938595
B39: B. Matriz de distancias y relaciones
B40: Potencia de tensión, n: | D40: 7 | E40: n = 0, exluye la distancia de la ponderación. Valores recomendados entre 0.5 y 5, generalmente se usa 2 para disminuir la desviación estándar estimada.
B41: Estación virtual a completar | C41: Latitud, ° | D41: Longitud, ° | E41: Estación testigo | F41: Latitud, ° | G41: Longitud, ° | H41: d, distancia ° | I41: 1/dn, inverso de la distancia | J41: ∑ 1/dn | K41: PMax24h / dn | L41: ∑ PMax24h / dn | M41: Relación PMax24h | N41: PMaxDesvStd / dn | O41: ∑ PMaxDesvStd / dn | P41: Relación PMaxDesvStd
B42: =C33 -> Virtual1 | C42: =E33 -> 10.064161 | D42: =F33 -> -72.937769 | E42: =C7 -> 25020230 | F42: =E7 -> 9.5621667 | G42: =F7 -> -73.339472 | H42: =((ABS($C$42-F42)^2)+(ABS($D$42-G42)^2))^0.5 -> 0.64293373 | I42: =1/H42^$D$40 -> 22.020973 | J42: =SUM(I42:I67) -> 56101.833 | K42: =H7/H42^$D$40 -> 2329.8344 | L42: =SUM(K42:K67) -> 5380674.1 | M42: =L42/J42 -> 95.90906 | N42: =I7/H42^$D$40 -> 852.81646 | O42: =SUM(N42:N67) -> 1783564.8 | P42: =O42/J42 -> 31.791561
E43: =C8 -> 25020240 | F43: =E8 -> 9.4104722 | G43: =F8 -> -73.890417 | H43: =((ABS($C$42-F43)^2)+(ABS($D$42-G43)^2))^0.5 -> 1.1553556 | I43: =1/H43^$D$40 -> 0.36390686 | K43: =H8/H43^$D$40 -> 38.172896 | N43: =I8/H43^$D$40 -> 10.183848
E44: =C9 -> 25020250 | F44: =E9 -> 9.1971944 | G44: =F9 -> -73.541944 | H44: =((ABS($C$42-F44)^2)+(ABS($D$42-G44)^2))^0.5 -> 1.0567209 | I44: =1/H44^$D$40 -> 0.67963861 | K44: =H9/H44^$D$40 -> 73.80481 | N44: =I9/H44^$D$40 -> 18.562149
E45: =C10 -> 25020260 | F45: =E10 -> 9.3970278 | G45: =F10 -> -73.488028 | H45: =((ABS($C$42-F45)^2)+(ABS($D$42-G45)^2))^0.5 -> 0.86478405 | I45: =1/H45^$D$40 -> 2.764689 | K45: =H10/H45^$D$40 -> 295.53817 | N45: =I10/H45^$D$40 -> 88.152985
E46: =C11 -> 25020280 | F46: =E11 -> 9.6065278 | G46: =F11 -> -73.611972 | H46: =((ABS($C$42-F46)^2)+(ABS($D$42-G46)^2))^0.5 -> 0.81484854 | I46: =1/H46^$D$40 -> 4.1923907 | K46: =H11/H46^$D$40 -> 457.25008 | N46: =I11/H46^$D$40 -> 152.64743
E47: =C12 -> 25020690 | F47: =E12 -> 9.4232778 | G47: =F12 -> -73.410944 | H47: =((ABS($C$42-F47)^2)+(ABS($D$42-G47)^2))^0.5 -> 0.79663436 | I47: =1/H47^$D$40 -> 4.9111903 | K47: =H12/H47^$D$40 -> 477.64474 | N47: =I12/H47^$D$40 -> 134.96826
E48: =C13 -> 25020920 | F48: =E13 -> 9.2166667 | G48: =F13 -> -73.416667 | H48: =((ABS($C$42-F48)^2)+(ABS($D$42-G48)^2))^0.5 -> 0.97344215 | I48: =1/H48^$D$40 -> 1.2073383 | K48: =H13/H48^$D$40 -> 121.82378 | N48: =I13/H48^$D$40 -> 58.833201
E49: =C14 -> 25021240 | F49: =E14 -> 9.2600833 | G49: =F14 -> -73.809861 | H49: =((ABS($C$42-F49)^2)+(ABS($D$42-G49)^2))^0.5 -> 1.1862064 | I49: =1/H49^$D$40 -> 0.3026065 | K49: =H14/H49^$D$40 -> 32.176627 | N49: =I14/H49^$D$40 -> 6.6823673
E50: =C15 -> 25021650 | F50: =E15 -> 9.5573889 | G50: =F15 -> -73.876194 | H50: =((ABS($C$42-F50)^2)+(ABS($D$42-G50)^2))^0.5 -> 1.0665178 | I50: =1/H50^$D$40 -> 0.63712282 | K50: =H15/H50^$D$40 -> 64.862744 | N50: =I15/H50^$D$40 -> 17.941501
E51: =C16 -> 25025250 | F51: =E16 -> 9.3610278 | G51: =F16 -> -73.593389 | H51: =((ABS($C$42-F51)^2)+(ABS($D$42-G51)^2))^0.5 -> 0.96137078 | I51: =1/H51^$D$40 -> 1.3175393 | K51: =H16/H51^$D$40 -> 142.34825 | N51: =I16/H51^$D$40 -> 51.423549
E52: =C17 -> 28010070 | F52: =E17 -> 10.1855 | G52: =F17 -> -73.467111 | H52: =((ABS($C$42-F52)^2)+(ABS($D$42-G52)^2))^0.5 -> 0.5430711 | I52: =1/H52^$D$40 -> 71.779948 | K52: =H17/H52^$D$40 -> 5218.0341 | N52: =I17/H52^$D$40 -> 2769.7643
E53: =C18 -> 28020080 | F53: =E18 -> 9.8480833 | G53: =F18 -> -73.462194 | H53: =((ABS($C$42-F53)^2)+(ABS($D$42-G53)^2))^0.5 -> 0.56719626 | I53: =1/H53^$D$40 -> 52.950062 | K53: =H18/H53^$D$40 -> 5327.8624 | N53: =I18/H53^$D$40 -> 2284.9884
E54: =C19 -> 28020150 | F54: =E19 -> 10.029972 | G54: =F19 -> -73.668833 | H54: =((ABS($C$42-F54)^2)+(ABS($D$42-G54)^2))^0.5 -> 0.73186333 | I54: =1/H54^$D$40 -> 8.8918086 | K54: =H19/H54^$D$40 -> 642.04368 | N54: =I19/H54^$D$40 -> 317.1156
... E67: =C32 -> 28040350 | F67: =E32 -> 9.6569722 | G67: =F32 -> -73.743694 | H67: =((ABS($C$42-F67)^2)+(ABS($D$42-G67)^2))^0.5 -> 0.9029499 | I67: =1/H67^$D$40 -> 2.0434049 | K67: =H32/H67^$D$40 -> 229.38789 | N67: =I32/H67^$D$40 -> 151.2513
...

Sheet Metodo2
B2: Método 2: estimación de la precipitación máxima en estaciones virtuales a partir de la relación entre la precipitación máxima, la precipitación media y el valor inverso de la distancia
B3: (Máximos obtenidos del análisis realizado previamente y almacenado en el archivo ..\HIDG\Tablas\PMax24h_v0.xls)
B5: A. Estaciones | F5: Zonal Real >> | G5: =AVERAGE(G7:G32) -> 136.92308 | H5: =AVERAGE(H7:H32) -> 97.615969 | I5: =AVERAGE(I7:I32) -> 33.053471 | J5: =AVERAGE(J7:J32) -> 1645.9647 | K5: =AVERAGE(K7:K32) -> 1444.0176 | L5: =AVERAGE(L7:L32) -> 0.068346404 | M5: =AVERAGE(M7:M32) -> 0.023441902
B6: Tipo | C6: IdEstación | D6: Nombre | E6: Latitud, ° | F6: Longitud, ° | G6: Altitud, m | H6: PMax24h, mm | I6: PMaxDesvStd, mm | J6: Pmed CKCM, mm | K6: Pmed KDE, mm | L6: R, PMax24h | M6: R, PMaxDesvStd
A7: 1 | B7: Estación real | C7: 25020230 | D7: JAGUA LA [25020230] | E7: 9.5621667 | F7: -73.339472 | G7: 135 | H7: 105.8007 | I7: 38.727465 | J7: 1619.92 | K7: 1539.7109 | L7: =H7/K7 -> 0.068714652 | M7: =I7/K7 -> 0.025152426
A8: 2 | C8: 25020240 | D8: CANAL EL [25020240] | E8: 9.4104722 | F8: -73.890417 | G8: 55 | H8: 104.89744 | I8: 27.984765 | J8: 1626.6072 | K8: 1658.5162 | L8: =H8/K8 -> 0.063247759 | M8: =I8/K8 -> 0.016873374
A9: 3 | C9: 25020250 | D9: CURUMANI [25020250] | E9: 9.1971944 | F9: -73.541944 | G9: 61 | H9: 108.5942 | I9: 27.311794 | J9: 2081.5364 | K9: 1841.3989 | L9: =H9/K9 -> 0.058973749 | M9: =I9/K9 -> 0.01483209
A10: 4 | C10: 25020260 | D10: RINCONHONDO [25020260] | E10: 9.3970278 | F10: -73.488028 | G10: 64 | H10: 106.89744 | I10: 31.885317 | J10: 1915.1008 | K10: 1783.049 | L10: =H10/K10 -> 0.059952048 | M10: =I10/K10 -> 0.017882468
A11: 5 | C11: 25020280 | D11: LOMA LA [25020280] | E11: 9.6065278 | F11: -73.611972 | G11: 42 | H11: 109.06667 | I11: 36.410592 | J11: 1675.7328 | K11: 1375.6261 | L11: =H11/K11 -> 0.07928511 | M11: =I11/K11 -> 0.026468378
A12: 6 | C12: 25020690 | D12: POPONTE [25020690] | E12: 9.4232778 | F12: -73.410944 | G12: 91 | H12: 97.25641 | I12: 27.481781 | J12: 1823.3492 | K12: 1766.8431 | L12: =H12/K12 -> 0.0550453 | M12: =I12/K12 -> 0.015554172
A13: 7 | C13: 25020920 | D13: PRIMAVERA LA [25020920] | E13: 9.2166667 | F13: -73.416667 | G13: 1268 | H13: 100.90278 | I13: 48.729675 | J13: 1681.7874 | K13: 1487.2303 | L13: =H13/K13 -> 0.067846099 | M13: =I13/K13 -> 0.032765385
A14: 8 | C14: 25021240 | D14: CHIMICHAGUA [25021240] | E14: 9.2600833 | F14: -73.809861 | G14: 33 | H14: 106.33158 | I14: 22.082696 | J14: 1831.9044 | K14: 1680.5377 | L14: =H14/K14 -> 0.063272355 | M14: =I14/K14 -> 0.013140256
A15: 9 | C15: 25021650 | D15: YUCAL EL [25021650] | E15: 9.5573889 | F15: -73.876194 | G15: 43 | H15: 101.80571 | I15: 28.160192 | J15: 1473.9426 | K15: 1523.7444 | L15: =H15/K15 -> 0.066812856 | M15: =I15/K15 -> 0.018480916
A16: 10 | C16: 25025250 | D16: CHIRIGUANA [25025250] | E16: 9.3610278 | F16: -73.593389 | G16: 32 | H16: 108.04098 | I16: 39.029992 | J16: 1903.2529 | K16: 1829.2357 | L16: =H16/K16 -> 0.059063456 | M16: =I16/K16 -> 0.021336775
A17: 11 | C17: 28010070 | D17: VILLA MARLENE [28010070] | E17: 10.1855 | F17: -73.467111 | G17: 78 | H17: 72.694872 | I17: 38.58688 | J17: 1522.314 | K17: 1384.5342 | L17: =H17/K17 -> 0.052504931 | M17: =I17/K17 -> 0.027869937
A18: 12 | C18: 28020080 | D18: PLAYAS LAS HACIENDA [28020080] | E18: 9.8480833 | F18: -73.462194 | G18: 58 | H18: 100.62051 | I18: 43.153649 | J18: 1333.0487 | K18: 1185.1753 | L18: =H18/K18 -> 0.084899266 | M18: =I18/K18 -> 0.036411196
A19: 13 | C19: 28020150 | D19: ESPERANZA LA HACIENDA [28020150] | E19: 10.029972 | F19: -73.668833 | G19: 83 | H19: 72.206197 | I19: 35.663791 | J19: 1239.9448 | K19: 1088.6627 | L19: =H19/K19 -> 0.066325589 | M19: =I19/K19 -> 0.032759265
... A32: 26 | C32: 28040350 | D32: PASO EL [28040350] | E32: 9.6569722 | F32: -73.743694 | G32: 34 | H32: 112.25768 | I32: 74.019251 | J32: 1448.6624 | K32: 1359.0289 | L32: =H32/K32 -> 0.082601391 | M32: =I32/K32 -> 0.054464809
A33: 27 | B33: Estación virtual | C33: Virtual1 | D33: Virtual 1 | E33: 10.064161 | F33: -72.937769 | G33: 2871 | H33: =K33*$M$42 -> 86.669481 | I33: =K33*P42 -> 28.819288 | J33: 1653.0728 | K33: 1247.8606 | L33: No requerida | M33: No requerida
A34: 28 | C34: Virtual2 | D34: Virtual 2 | E34: 9.739112 | F34: -72.944279 | G34: 1323 | H34: =K34*$M$68 -> 116.88997 | I34: =K34*P68 -> 39.003435 | J34: 2357.9204 | K34: 1692.7278
A35: 29 | C35: Virtual3 | D35: Virtual 3 | E35: 9.55008 | F35: -73.027958 | G35: 595 | H35: =K35*$M$94 -> 129.63112 | I35: =K35*P94 -> 43.697485 | J35: 3171.7471 | K35: 1892.2783
A36: 30 | C36: Virtual4 | D36: Virtual 4 | E36: 9.395879 | F36: -73.196423 | G36: 2467 | H36: =K36*$M$120 -> 111.13931 | I36: =K36*P120 -> 37.937478 | J36: 2240.1467 | K36: 1647.4474
F37: Zonal Virtual >> | G37: =AVERAGE(G33:G36) -> 1814 | H37: =AVERAGE(H33:H36) -> 111.08247 | I37: =AVERAGE(I33:I36) -> 37.364421 | J37: =AVERAGE(J33:J36) -> 2355.7217 | K37: =AVERAGE(K33:K36) -> 1620.0785
B39: B. Matriz de distancias y relaciones
B40: Potencia de tensión, n: | D40: 1 | E40: n = 0, exluye la distancia de la ponderación. Valores recomendados entre 0.5 y 5, generalmente se usa 2 para disminuir la desviación estándar estimada.
B41: Estación virtual a completar | C41: Latitud, ° | D41: Longitud, ° | E41: Estación testigo | F41: Latitud, ° | G41: Longitud, ° | H41: d, distancia ° | I41: 1/dn, inverso de la distancia | J41: ∑ 1/dn | K41: R / dn, PMax24h | L41: ∑ R/dn, PMax24h | M41: Relación PMax24h | N41: R / dn, PMaxDesvStd | O41: ∑ R/dn, PMaxDesvStd | P41: Relación PMaxDesvStd
B42: =C33 -> Virtual1 | C42: =E33 -> 10.064161 | D42: =F33 -> -72.937769 | E42: =C7 -> 25020230 | F42: =E7 -> 9.5621667 | G42: =F7 -> -73.339472 | H42: =((ABS($C$42-F42)^2)+(ABS($D$42-G42)^2))^0.5 -> 0.64293373 | I42: =1/H42^$D$40 -> 1.5553702 | J42: =SUM(I42:I67) -> 45.120639 | K42: =L7/H42^$D$40 -> 0.10687672 | L42: =SUM(K42:K67) -> 3.1338295 | M42: =L42/J42 -> 0.069454458 | N42: =M7/H42^$D$40 -> 0.039121334 | O42: =SUM(N42:N67) -> 1.0420593 | P42: =O42/J42 -> 0.023094958
E43: =C8 -> 25020240 | F43: =E8 -> 9.4104722 | G43: =F8 -> -73.890417 | H43: =((ABS($C$42-F43)^2)+(ABS($D$42-G43)^2))^0.5 -> 1.1553556 | I43: =1/H43^$D$40 -> 0.86553437 | K43: =L8/H43^$D$40 -> 0.05474311 | N43: =M8/H43^$D$40 -> 0.014604486
E44: =C9 -> 25020250 | F44: =E9 -> 9.1971944 | G44: =F9 -> -73.541944 | H44: =((ABS($C$42-F44)^2)+(ABS($D$42-G44)^2))^0.5 -> 1.0567209 | I44: =1/H44^$D$40 -> 0.94632371 | K44: =L9/H44^$D$40 -> 0.055808257 | N44: =M9/H44^$D$40 -> 0.014035958
E45: =C10 -> 25020260 | F45: =E10 -> 9.3970278 | G45: =F10 -> -73.488028 | H45: =((ABS($C$42-F45)^2)+(ABS($D$42-G45)^2))^0.5 -> 0.86478405 | I45: =1/H45^$D$40 -> 1.156358 | K45: =L10/H45^$D$40 -> 0.069326033 | N45: =M10/H45^$D$40 -> 0.020678536
E46: =C11 -> 25020280 | F46: =E11 -> 9.6065278 | G46: =F11 -> -73.611972 | H46: =((ABS($C$42-F46)^2)+(ABS($D$42-G46)^2))^0.5 -> 0.81484854 | I46: =1/H46^$D$40 -> 1.2272219 | K46: =L11/H46^$D$40 -> 0.097300426 | N46: =M11/H46^$D$40 -> 0.032482574
E47: =C12 -> 25020690 | F47: =E12 -> 9.4232778 | G47: =F12 -> -73.410944 | H47: =((ABS($C$42-F47)^2)+(ABS($D$42-G47)^2))^0.5 -> 0.79663436 | I47: =1/H47^$D$40 -> 1.255281 | K47: =L12/H47^$D$40 -> 0.069097321 | N47: =M12/H47^$D$40 -> 0.019524857
E48: =C13 -> 25020920 | F48: =E13 -> 9.2166667 | G48: =F13 -> -73.416667 | H48: =((ABS($C$42-F48)^2)+(ABS($D$42-G48)^2))^0.5 -> 0.97344215 | I48: =1/H48^$D$40 -> 1.0272824 | K48: =L13/H48^$D$40 -> 0.069697104 | N48: =M13/H48^$D$40 -> 0.033659304
E49: =C14 -> 25021240 | F49: =E14 -> 9.2600833 | G49: =F14 -> -73.809861 | H49: =((ABS($C$42-F49)^2)+(ABS($D$42-G49)^2))^0.5 -> 1.1862064 | I49: =1/H49^$D$40 -> 0.84302363 | K49: =L14/H49^$D$40 -> 0.05334009 | N49: =M14/H49^$D$40 -> 0.011077546
E50: =C15 -> 25021650 | F50: =E15 -> 9.5573889 | G50: =F15 -> -73.876194 | H50: =((ABS($C$42-F50)^2)+(ABS($D$42-G50)^2))^0.5 -> 1.0665178 | I50: =1/H50^$D$40 -> 0.93763083 | K50: =L15/H50^$D$40 -> 0.062645794 | N50: =M15/H50^$D$40 -> 0.017328277
E51: =C16 -> 25025250 | F51: =E16 -> 9.3610278 | G51: =F16 -> -73.593389 | H51: =((ABS($C$42-F51)^2)+(ABS($D$42-G51)^2))^0.5 -> 0.96137078 | I51: =1/H51^$D$40 -> 1.0401814 | K51: =L16/H51^$D$40 -> 0.061436709 | N51: =M16/H51^$D$40 -> 0.022194117
E52: =C17 -> 28010070 | F52: =E17 -> 10.1855 | G52: =F17 -> -73.467111 | H52: =((ABS($C$42-F52)^2)+(ABS($D$42-G52)^2))^0.5 -> 0.5430711 | I52: =1/H52^$D$40 -> 1.8413795 | K52: =L17/H52^$D$40 -> 0.096681504 | N52: =M17/H52^$D$40 -> 0.051319131
E53: =C18 -> 28020080 | F53: =E18 -> 9.8480833 | G53: =F18 -> -73.462194 | H53: =((ABS($C$42-F53)^2)+(ABS($D$42-G53)^2))^0.5 -> 0.56719626 | I53: =1/H53^$D$40 -> 1.7630582 | K53: =L18/H53^$D$40 -> 0.14968234 | N53: =M18/H53^$D$40 -> 0.064195056
E54: =C19 -> 28020150 | F54: =E19 -> 10.029972 | G54: =F19 -> -73.668833 | H54: =((ABS($C$42-F54)^2)+(ABS($D$42-G54)^2))^0.5 -> 0.73186333 | I54: =1/H54^$D$40 -> 1.3663753 | K54: =L19/H54^$D$40 -> 0.09062565 | N54: =M19/H54^$D$40 -> 0.044761452
... E67: =C32 -> 28040350 | F67: =E32 -> 9.6569722 | G67: =F32 -> -73.743694 | H67: =((ABS($C$42-F67)^2)+(ABS($D$42-G67)^2))^0.5 -> 0.9029499 | I67: =1/H67^$D$40 -> 1.1074812 | K67: =L32/H67^$D$40 -> 0.091479484 | N67: =M32/H67^$D$40 -> 0.06031875
...

Sheet Metodo3
B2: Método 3: estimación de la precipitación máxima en estaciones virtuales a partir de la relación entre la precipitación máxima, la precipitación media, la altitud y el valor inverso de la distancia
B3: (Máximos obtenidos del análisis realizado previamente y almacenado en el archivo ..\HIDG\Tablas\PMax24h_v0.xls)
B5: A. Estaciones | F5: Zonal Real >> | G5: =AVERAGE(G7:G32) -> 136.92308 | H5: =AVERAGE(H7:H32) -> 97.615969 | I5: =AVERAGE(I7:I32) -> 33.053471 | J5: =AVERAGE(J7:J32) -> 1645.9647 | K5: =AVERAGE(K7:K32) -> 1444.0176 | L5: =AVERAGE(L7:L32) -> 9.3134305 | M5: =AVERAGE(M7:M32) -> 3.5862674
B6: Tipo | C6: IdEstación | D6: Nombre | E6: Latitud, ° | F6: Longitud, ° | G6: Altitud, m | H6: PMax24h, mm | I6: PMaxDesvStd, mm | J6: Pmed CKCM, mm | K6: Pmed KDE, mm | L6: R, PMax24h | M6: R, PMaxDesvStd
A7: 1 | B7: Estación real | C7: 25020230 | D7: JAGUA LA [25020230] | E7: 9.5621667 | F7: -73.339472 | G7: 135 | H7: 105.8007 | I7: 38.727465 | J7: 1619.92 | K7: 1539.7109 | L7: =H7*G7/K7 -> 9.276478 | M7: =I7*G7/K7 -> 3.3955775
A8: 2 | C8: 25020240 | D8: CANAL EL [25020240] | E8: 9.4104722 | F8: -73.890417 | G8: 55 | H8: 104.89744 | I8: 27.984765 | J8: 1626.6072 | K8: 1658.5162 | L8: =H8*G8/K8 -> 3.4786268 | M8: =I8*G8/K8 -> 0.92803559
A9: 3 | C9: 25020250 | D9: CURUMANI [25020250] | E9: 9.1971944 | F9: -73.541944 | G9: 61 | H9: 108.5942 | I9: 27.311794 | J9: 2081.5364 | K9: 1841.3989 | L9: =H9*G9/K9 -> 3.5973987 | M9: =I9*G9/K9 -> 0.90475746
A10: 4 | C10: 25020260 | D10: RINCONHONDO [25020260] | E10: 9.3970278 | F10: -73.488028 | G10: 64 | H10: 106.89744 | I10: 31.885317 | J10: 1915.1008 | K10: 1783.049 | L10: =H10*G10/K10 -> 3.8369311 | M10: =I10*G10/K10 -> 1.144478
A11: 5 | C11: 25020280 | D11: LOMA LA [25020280] | E11: 9.6065278 | F11: -73.611972 | G11: 42 | H11: 109.06667 | I11: 36.410592 | J11: 1675.7328 | K11: 1375.6261 | L11: =H11*G11/K11 -> 3.3299746 | M11: =I11*G11/K11 -> 1.1116719
A12: 6 | C12: 25020690 | D12: POPONTE [25020690] | E12: 9.4232778 | F12: -73.410944 | G12: 91 | H12: 97.25641 | I12: 27.481781 | J12: 1823.3492 | K12: 1766.8431 | L12: =H12*G12/K12 -> 5.0091223 | M12: =I12*G12/K12 -> 1.4154296
A13: 7 | C13: 25020920 | D13: PRIMAVERA LA [25020920] | E13: 9.2166667 | F13: -73.416667 | G13: 1268 | H13: 100.90278 | I13: 48.729675 | J13: 1681.7874 | K13: 1487.2303 | L13: =H13*G13/K13 -> 86.028854 | M13: =I13*G13/K13 -> 41.546508
A14: 8 | C14: 25021240 | D14: CHIMICHAGUA [25021240] | E14: 9.2600833 | F14: -73.809861 | G14: 33 | H14: 106.33158 | I14: 22.082696 | J14: 1831.9044 | K14: 1680.5377 | L14: =H14*G14/K14 -> 2.0879877 | M14: =I14*G14/K14 -> 0.43362845
A15: 9 | C15: 25021650 | D15: YUCAL EL [25021650] | E15: 9.5573889 | F15: -73.876194 | G15: 43 | H15: 101.80571 | I15: 28.160192 | J15: 1473.9426 | K15: 1523.7444 | L15: =H15*G15/K15 -> 2.8729528 | M15: =I15*G15/K15 -> 0.7946794
A16: 10 | C16: 25025250 | D16: CHIRIGUANA [25025250] | E16: 9.3610278 | F16: -73.593389 | G16: 32 | H16: 108.04098 | I16: 39.029992 | J16: 1903.2529 | K16: 1829.2357 | L16: =H16*G16/K16 -> 1.8900306 | M16: =I16*G16/K16 -> 0.68277682
A17: 11 | C17: 28010070 | D17: VILLA MARLENE [28010070] | E17: 10.1855 | F17: -73.467111 | G17: 78 | H17: 72.694872 | I17: 38.58688 | J17: 1522.314 | K17: 1384.5342 | L17: =H17*G17/K17 -> 4.0953846 | M17: =I17*G17/K17 -> 2.1738551
A18: 12 | C18: 28020080 | D18: PLAYAS LAS HACIENDA [28020080] | E18: 9.8480833 | F18: -73.462194 | G18: 58 | H18: 100.62051 | I18: 43.153649 | J18: 1333.0487 | K18: 1185.1753 | L18: =H18*G18/K18 -> 4.9241574 | M18: =I18*G18/K18 -> 2.1118493
A19: 13 | C19: 28020150 | D19: ESPERANZA LA HACIENDA [28020150] | E19: 10.029972 | F19: -73.668833 | G19: 83 | H19: 72.206197 | I19: 35.663791 | J19: 1239.9448 | K19: 1088.6627 | L19: =H19*G19/K19 -> 5.5050239 | M19: =I19*G19/K19 -> 2.719019
... A32: 26 | C32: 28040350 | D32: PASO EL [28040350] | E32: 9.6569722 | F32: -73.743694 | G32: 34 | H32: 112.25768 | I32: 74.019251 | J32: 1448.6624 | K32: 1359.0289 | L32: =H32*G32/K32 -> 2.8084473 | M32: =I32*G32/K32 -> 1.8518035
A33: 27 | B33: Estación virtual | C33: Virtual1 | D33: Virtual 1 | E33: 10.064161 | F33: -72.937769 | G33: 2871 | H33: =K33*$M$42/G33 -> 4.5526918 | I33: =K33*P42/G33 -> 1.6233017 | J33: 1653.0728 | K33: 1247.8606 | L33: No requerida | M33: No requerida
A34: 28 | C34: Virtual2 | D34: Virtual 2 | E34: 9.739112 | F34: -72.944279 | G34: 1323 | H34: =K34*$M$68/G34 -> 12.335298 | I34: =K34*P68/G34 -> 4.5294797 | J34: 2357.9204 | K34: 1692.7278
A35: 29 | C35: Virtual3 | D35: Virtual 3 | E35: 9.55008 | F35: -73.027958 | G35: 595 | H35: =K35*$M$94/G35 -> 31.4461 | I35: =K35*P94/G35 -> 11.941183 | J35: 3171.7471 | K35: 1892.2783
A36: 30 | C36: Virtual4 | D36: Virtual 4 | E36: 9.395879 | F36: -73.196423 | G36: 2467 | H36: =K36*$M$120/G36 -> 7.4434259 | I36: =K36*P120/G36 -> 2.9910663 | J36: 2240.1467 | K36: 1647.4474
F37: Zonal Virtual >> | G37: =AVERAGE(G33:G36) -> 1814 | H37: =AVERAGE(H33:H36) -> 13.944379 | I37: =AVERAGE(I33:I36) -> 5.2712577 | J37: =AVERAGE(J33:J36) -> 2355.7217 | K37: =AVERAGE(K33:K36) -> 1620.0785
B39: B. Matriz de distancias y relaciones
B40: Potencia de tensión, n: | D40: 1 | E40: n = 0, exluye la distancia de la ponderación. Valores recomendados entre 0.5 y 5, generalmente se usa 2 para disminuir la desviación estándar estimada.
B41: Estación virtual a completar | C41: Latitud, ° | D41: Longitud, ° | E41: Estación testigo | F41: Latitud, ° | G41: Longitud, ° | H41: d, distancia ° | I41: 1/dn, inverso de la distancia | J41: ∑ 1/dn | K41: R / dn, PMax24h | L41: ∑ R/dn, PMax24h | M41: Relación PMax24h | N41: R / dn, PMaxDesvStd | O41: ∑ R/dn, PMaxDesvStd | P41: Relación PMaxDesvStd
B42: =C33 -> Virtual1 | C42: =E33 -> 10.064161 | D42: =F33 -> -72.937769 | E42: =C7 -> 25020230 | F42: =E7 -> 9.5621667 | G42: =F7 -> -73.339472 | H42: =((ABS($C$42-F42)^2)+(ABS($D$42-G42)^2))^0.5 -> 0.64293373 | I42: =1/H42^$D$40 -> 1.5553702 | J42: =SUM(I42:I67) -> 45.120639 | K42: =L7/H42^$D$40 -> 14.428358 | L42: =SUM(K42:K67) -> 472.61838 | M42: =L42/J42 -> 10.47455 | N42: =M7/H42^$D$40 -> 5.2813802 | O42: =SUM(N42:N67) -> 168.51617 | P42: =O42/J42 -> 3.7347914
E43: =C8 -> 25020240 | F43: =E8 -> 9.4104722 | G43: =F8 -> -73.890417 | H43: =((ABS($C$42-F43)^2)+(ABS($D$42-G43)^2))^0.5 -> 1.1553556 | I43: =1/H43^$D$40 -> 0.86553437 | K43: =L8/H43^$D$40 -> 3.010871 | N43: =M8/H43^$D$40 -> 0.80324671
E44: =C9 -> 25020250 | F44: =E9 -> 9.1971944 | G44: =F9 -> -73.541944 | H44: =((ABS($C$42-F44)^2)+(ABS($D$42-G44)^2))^0.5 -> 1.0567209 | I44: =1/H44^$D$40 -> 0.94632371 | K44: =L9/H44^$D$40 -> 3.4043037 | N44: =M9/H44^$D$40 -> 0.85619344
E45: =C10 -> 25020260 | F45: =E10 -> 9.3970278 | G45: =F10 -> -73.488028 | H45: =((ABS($C$42-F45)^2)+(ABS($D$42-G45)^2))^0.5 -> 0.86478405 | I45: =1/H45^$D$40 -> 1.156358 | K45: =L10/H45^$D$40 -> 4.4368661 | N45: =M10/H45^$D$40 -> 1.3234263
E46: =C11 -> 25020280 | F46: =E11 -> 9.6065278 | G46: =F11 -> -73.611972 | H46: =((ABS($C$42-F46)^2)+(ABS($D$42-G46)^2))^0.5 -> 0.81484854 | I46: =1/H46^$D$40 -> 1.2272219 | K46: =L11/H46^$D$40 -> 4.0866179 | N46: =M11/H46^$D$40 -> 1.3642681
E47: =C12 -> 25020690 | F47: =E12 -> 9.4232778 | G47: =F12 -> -73.410944 | H47: =((ABS($C$42-F47)^2)+(ABS($D$42-G47)^2))^0.5 -> 0.79663436 | I47: =1/H47^$D$40 -> 1.255281 | K47: =L12/H47^$D$40 -> 6.2878562 | N47: =M12/H47^$D$40 -> 1.776762
E48: =C13 -> 25020920 | F48: =E13 -> 9.2166667 | G48: =F13 -> -73.416667 | H48: =((ABS($C$42-F48)^2)+(ABS($D$42-G48)^2))^0.5 -> 0.97344215 | I48: =1/H48^$D$40 -> 1.0272824 | K48: =L13/H48^$D$40 -> 88.375928 | N48: =M13/H48^$D$40 -> 42.679997
E49: =C14 -> 25021240 | F49: =E14 -> 9.2600833 | G49: =F14 -> -73.809861 | H49: =((ABS($C$42-F49)^2)+(ABS($D$42-G49)^2))^0.5 -> 1.1862064 | I49: =1/H49^$D$40 -> 0.84302363 | K49: =L14/H49^$D$40 -> 1.760223 | N49: =M14/H49^$D$40 -> 0.36555903
E50: =C15 -> 25021650 | F50: =E15 -> 9.5573889 | G50: =F15 -> -73.876194 | H50: =((ABS($C$42-F50)^2)+(ABS($D$42-G50)^2))^0.5 -> 1.0665178 | I50: =1/H50^$D$40 -> 0.93763083 | K50: =L15/H50^$D$40 -> 2.6937691 | N50: =M15/H50^$D$40 -> 0.74511591
E51: =C16 -> 25025250 | F51: =E16 -> 9.3610278 | G51: =F16 -> -73.593389 | H51: =((ABS($C$42-F51)^2)+(ABS($D$42-G51)^2))^0.5 -> 0.96137078 | I51: =1/H51^$D$40 -> 1.0401814 | K51: =L16/H51^$D$40 -> 1.9659747 | N51: =M16/H51^$D$40 -> 0.71021174
E52: =C17 -> 28010070 | F52: =E17 -> 10.1855 | G52: =F17 -> -73.467111 | H52: =((ABS($C$42-F52)^2)+(ABS($D$42-G52)^2))^0.5 -> 0.5430711 | I52: =1/H52^$D$40 -> 1.8413795 | K52: =L17/H52^$D$40 -> 7.5411573 | N52: =M17/H52^$D$40 -> 4.0028922
E53: =C18 -> 28020080 | F53: =E18 -> 9.8480833 | G53: =F18 -> -73.462194 | H53: =((ABS($C$42-F53)^2)+(ABS($D$42-G53)^2))^0.5 -> 0.56719626 | I53: =1/H53^$D$40 -> 1.7630582 | K53: =L18/H53^$D$40 -> 8.681576 | N53: =M18/H53^$D$40 -> 3.7233132
E54: =C19 -> 28020150 | F54: =E19 -> 10.029972 | G54: =F19 -> -73.668833 | H54: =((ABS($C$42-F54)^2)+(ABS($D$42-G54)^2))^0.5 -> 0.73186333 | I54: =1/H54^$D$40 -> 1.3663753 | K54: =L19/H54^$D$40 -> 7.5219289 | N54: =M19/H54^$D$40 -> 3.7152005
... E67: =C32 -> 28040350 | F67: =E32 -> 9.6569722 | G67: =F32 -> -73.743694 | H67: =((ABS($C$42-F67)^2)+(ABS($D$42-G67)^2))^0.5 -> 0.9029499 | I67: =1/H67^$D$40 -> 1.1074812 | K67: =L32/H67^$D$40 -> 3.1103025 | N67: =M32/H67^$D$40 -> 2.0508375
...

Sheet Metodo4
B2: Método 4: estimación de la precipitación máxima en estaciones virtuales a partir de la relación entre la precipitación máxima, la precipitación media, el logaritmo de la altitud y el valor inverso de la distancia
B3: (Máximos obtenidos del análisis realizado previamente y almacenado en el archivo ..\HIDG\Tablas\PMax24h_v0.xls)
B5: A. Estaciones | F5: Zonal Real >> | G5: =AVERAGE(G7:G32) -> 136.92308 | H5: =AVERAGE(H7:H32) -> 1.916816 | I5: =AVERAGE(I7:I32) -> 97.615969 | J5: =AVERAGE(J7:J32) -> 33.053471 | K5: =AVERAGE(K7:K32) -> 1645.9647 | L5: =AVERAGE(L7:L32) -> 1444.0176 | M5: =AVERAGE(M7:M32) -> 0.13096582 | N5: =AVERAGE(N7:N32) -> 0.045085996
B6: Tipo | C6: IdEstación | D6: Nombre | E6: Latitud, ° | F6: Longitud, ° | G6: Altitud, m | H6: Log10 (altitud) | I6: PMax24h, mm | J6: PMaxDesvStd, mm | K6: Pmed CKCM, mm | L6: Pmed KDE, mm | M6: R, PMax24h | N6: R, PMaxDesvStd
A7: 1 | B7: Estación real | C7: 25020230 | D7: JAGUA LA [25020230] | E7: 9.5621667 | F7: -73.339472 | G7: 135 | H7: =LOG10(G7) -> 2.1303338 | I7: 105.8007 | J7: 38.727465 | K7: 1619.92 | L7: 1539.7109 | M7: =I7*H7/L7 -> 0.14638514 | N7: =J7*H7/L7 -> 0.053583062
A8: 2 | C8: 25020240 | D8: CANAL EL [25020240] | E8: 9.4104722 | F8: -73.890417 | G8: 55 | H8: =LOG10(G8) -> 1.7403627 | I8: 104.89744 | J8: 27.984765 | K8: 1626.6072 | L8: 1658.5162 | M8: =I8*H8/L8 -> 0.11007404 | N8: =J8*H8/L8 -> 0.029365791
A9: 3 | C9: 25020250 | D9: CURUMANI [25020250] | E9: 9.1971944 | F9: -73.541944 | G9: 61 | H9: =LOG10(G9) -> 1.7853298 | I9: 108.5942 | J9: 27.311794 | K9: 2081.5364 | L9: 1841.3989 | M9: =I9*H9/L9 -> 0.10528759 | N9: =J9*H9/L9 -> 0.026480172
A10: 4 | C10: 25020260 | D10: RINCONHONDO [25020260] | E10: 9.3970278 | F10: -73.488028 | G10: 64 | H10: =LOG10(G10) -> 1.80618 | I10: 106.89744 | J10: 31.885317 | K10: 1915.1008 | L10: 1783.049 | M10: =I10*H10/L10 -> 0.10828419 | N10: =J10*H10/L10 -> 0.032298956
A11: 5 | C11: 25020280 | D11: LOMA LA [25020280] | E11: 9.6065278 | F11: -73.611972 | G11: 42 | H11: =LOG10(G11) -> 1.6232493 | I11: 109.06667 | J11: 36.410592 | K11: 1675.7328 | L11: 1375.6261 | M11: =I11*H11/L11 -> 0.1286995 | N11: =J11*H11/L11 -> 0.042964777
A12: 6 | C12: 25020690 | D12: POPONTE [25020690] | E12: 9.4232778 | F12: -73.410944 | G12: 91 | H12: =LOG10(G12) -> 1.9590414 | I12: 97.25641 | J12: 27.481781 | K12: 1823.3492 | L12: 1766.8431 | M12: =I12*H12/L12 -> 0.10783602 | N12: =J12*H12/L12 -> 0.030471266
A13: 7 | C13: 25020920 | D13: PRIMAVERA LA [25020920] | E13: 9.2166667 | F13: -73.416667 | G13: 1268 | H13: =LOG10(G13) -> 3.1031193 | I13: 100.90278 | J13: 48.729675 | K13: 1681.7874 | L13: 1487.2303 | M13: =I13*H13/L13 -> 0.21053454 | N13: =J13*H13/L13 -> 0.1016749
A14: 8 | C14: 25021240 | D14: CHIMICHAGUA [25021240] | E14: 9.2600833 | F14: -73.809861 | G14: 33 | H14: =LOG10(G14) -> 1.5185139 | I14: 106.33158 | J14: 22.082696 | K14: 1831.9044 | L14: 1680.5377 | M14: =I14*H14/L14 -> 0.096079953 | N14: =J14*H14/L14 -> 0.019953662
A15: 9 | C15: 25021650 | D15: YUCAL EL [25021650] | E15: 9.5573889 | F15: -73.876194 | G15: 43 | H15: =LOG10(G15) -> 1.6334685 | I15: 101.80571 | J15: 28.160192 | K15: 1473.9426 | L15: 1523.7444 | M15: =I15*H15/L15 -> 0.10913669 | N15: =J15*H15/L15 -> 0.030187994
A16: 10 | C16: 25025250 | D16: CHIRIGUANA [25025250] | E16: 9.3610278 | F16: -73.593389 | G16: 32 | H16: =LOG10(G16) -> 1.50515 | I16: 108.04098 | J16: 39.029992 | K16: 1903.2529 | L16: 1829.2357 | M16: =I16*H16/L16 -> 0.08889936 | N16: =J16*H16/L16 -> 0.032115047
A17: 11 | C17: 28010070 | D17: VILLA MARLENE [28010070] | E17: 10.1855 | F17: -73.467111 | G17: 78 | H17: =LOG10(G17) -> 1.8920946 | I17: 72.694872 | J17: 38.58688 | K17: 1522.314 | L17: 1384.5342 | M17: =I17*H17/L17 -> 0.099344297 | N17: =J17*H17/L17 -> 0.052732557
A18: 12 | C18: 28020080 | D18: PLAYAS LAS HACIENDA [28020080] | E18: 9.8480833 | F18: -73.462194 | G18: 58 | H18: =LOG10(G18) -> 1.763428 | I18: 100.62051 | J18: 43.153649 | K18: 1333.0487 | L18: 1185.1753 | M18: =I18*H18/L18 -> 0.14971374 | N18: =J18*H18/L18 -> 0.064208522
A19: 13 | C19: 28020150 | D19: ESPERANZA LA HACIENDA [28020150] | E19: 10.029972 | F19: -73.668833 | G19: 83 | H19: =LOG10(G19) -> 1.9190781 | I19: 72.206197 | J19: 35.663791 | K19: 1239.9448 | L19: 1088.6627 | M19: =I19*H19/L19 -> 0.12728399 | N19: =J19*H19/L19 -> 0.062867588
... A32: 26 | C32: 28040350 | D32: PASO EL [28040350] | E32: 9.6569722 | F32: -73.743694 | G32: 34 | H32: =LOG10(G32) -> 1.5314789 | I32: 112.25768 | J32: 74.019251 | K32: 1448.6624 | L32: 1359.0289 | M32: =I32*H32/L32 -> 0.12650229 | N32: =J32*H32/L32 -> 0.083411707
A33: 27 | B33: Estación virtual | C33: Virtual1 | D33: Virtual 1 | E33: 10.064161 | F33: -72.937769 | G33: 2871 | H33: =LOG10(G33) -> 3.4580332 | I33: =L33*$M$42/H33 -> 50.044692 | J33: =L33*P42/H33 -> 16.637085 | K33: 1653.0728 | L33: 1247.8606 | M33: No requerida | N33: No requerida
A34: 28 | C34: Virtual2 | D34: Virtual 2 | E34: 9.739112 | F34: -72.944279 | G34: 1323 | H34: =LOG10(G34) -> 3.1215598 | I34: =L34*$M$68/H34 -> 73.557817 | J34: =L34*P68/H34 -> 24.573586 | K34: 2357.9204 | L34: 1692.7278
A35: 29 | C35: Virtual3 | D35: Virtual 3 | E35: 9.55008 | F35: -73.027958 | G35: 595 | H35: =LOG10(G35) -> 2.774517 | I35: =L35*$M$94/H35 -> 91.52756 | J35: =L35*P94/H35 -> 30.972406 | K35: 3171.7471 | L35: 1892.2783
A36: 30 | C36: Virtual4 | D36: Virtual 4 | E36: 9.395879 | F36: -73.196423 | G36: 2467 | H36: =LOG10(G36) -> 3.3921691 | I36: =L36*$M$120/H36 -> 64.32826 | J36: =L36*P120/H36 -> 22.193266 | K36: 2240.1467 | L36: 1647.4474
F37: Zonal Virtual >> | G37: =AVERAGE(G33:G36) -> 1814 | H37: =AVERAGE(H33:H36) -> 3.1865698 | I37: =AVERAGE(I33:I36) -> 69.864582 | J37: =AVERAGE(J33:J36) -> 23.594086 | K37: =AVERAGE(K33:K36) -> 2355.7217 | L37: =AVERAGE(L33:L36) -> 1620.0785
B39: B. Matriz de distancias y relaciones
B40: Potencia de tensión, n: | D40: 1 | E40: n = 0, exluye la distancia de la ponderación. Valores recomendados entre 0.5 y 5, generalmente se usa 2 para disminuir la desviación estándar estimada.
B41: Estación virtual a completar | C41: Latitud, ° | D41: Longitud, ° | E41: Estación testigo | F41: Latitud, ° | G41: Longitud, ° | H41: d, distancia ° | I41: 1/dn, inverso de la distancia | J41: ∑ 1/dn | K41: R / dn, PMax24h | L41: ∑ R/dn, PMax24h | M41: Relación PMax24h | N41: R / dn, PMaxDesvStd | O41: ∑ R/dn, PMaxDesvStd | P41: Relación PMaxDesvStd
B42: =C33 -> Virtual1 | C42: =E33 -> 10.064161 | D42: =F33 -> -72.937769 | E42: =C7 -> 25020230 | F42: =E7 -> 9.5621667 | G42: =F7 -> -73.339472 | H42: =((ABS($C$42-F42)^2)+(ABS($D$42-G42)^2))^0.5 -> 0.64293373 | I42: =1/H42^$D$40 -> 1.5553702 | J42: =SUM(I42:I67) -> 45.120639 | K42: =M7/H42^$D$40 -> 0.22768309 | L42: =SUM(K42:K67) -> 6.257435 | M42: =L42/J42 -> 0.13868232 | N42: =N7/H42^$D$40 -> 0.0833415 | O42: =SUM(N42:N67) -> 2.0802502 | P42: =O42/J42 -> 0.046104183
E43: =C8 -> 25020240 | F43: =E8 -> 9.4104722 | G43: =F8 -> -73.890417 | H43: =((ABS($C$42-F43)^2)+(ABS($D$42-G43)^2))^0.5 -> 1.1553556 | I43: =1/H43^$D$40 -> 0.86553437 | K43: =M8/H43^$D$40 -> 0.095272866 | N43: =N8/H43^$D$40 -> 0.025417102
E44: =C9 -> 25020250 | F44: =E9 -> 9.1971944 | G44: =F9 -> -73.541944 | H44: =((ABS($C$42-F44)^2)+(ABS($D$42-G44)^2))^0.5 -> 1.0567209 | I44: =1/H44^$D$40 -> 0.94632371 | K44: =M9/H44^$D$40 -> 0.099636146 | N44: =N9/H44^$D$40 -> 0.025058815
E45: =C10 -> 25020260 | F45: =E10 -> 9.3970278 | G45: =F10 -> -73.488028 | H45: =((ABS($C$42-F45)^2)+(ABS($D$42-G45)^2))^0.5 -> 0.86478405 | I45: =1/H45^$D$40 -> 1.156358 | K45: =M10/H45^$D$40 -> 0.12521529 | N45: =N10/H45^$D$40 -> 0.037349158
E46: =C11 -> 25020280 | F46: =E11 -> 9.6065278 | G46: =F11 -> -73.611972 | H46: =((ABS($C$42-F46)^2)+(ABS($D$42-G46)^2))^0.5 -> 0.81484854 | I46: =1/H46^$D$40 -> 1.2272219 | K46: =M11/H46^$D$40 -> 0.15794285 | N46: =N11/H46^$D$40 -> 0.052727316
E47: =C12 -> 25020690 | F47: =E12 -> 9.4232778 | G47: =F12 -> -73.410944 | H47: =((ABS($C$42-F47)^2)+(ABS($D$42-G47)^2))^0.5 -> 0.79663436 | I47: =1/H47^$D$40 -> 1.255281 | K47: =M12/H47^$D$40 -> 0.13536451 | N47: =N12/H47^$D$40 -> 0.038250002
E48: =C13 -> 25020920 | F48: =E13 -> 9.2166667 | G48: =F13 -> -73.416667 | H48: =((ABS($C$42-F48)^2)+(ABS($D$42-G48)^2))^0.5 -> 0.97344215 | I48: =1/H48^$D$40 -> 1.0272824 | K48: =M13/H48^$D$40 -> 0.21627843 | N48: =N13/H48^$D$40 -> 0.10444883
E49: =C14 -> 25021240 | F49: =E14 -> 9.2600833 | G49: =F14 -> -73.809861 | H49: =((ABS($C$42-F49)^2)+(ABS($D$42-G49)^2))^0.5 -> 1.1862064 | I49: =1/H49^$D$40 -> 0.84302363 | K49: =M14/H49^$D$40 -> 0.080997671 | N49: =N14/H49^$D$40 -> 0.016821409
E50: =C15 -> 25021650 | F50: =E15 -> 9.5573889 | G50: =F15 -> -73.876194 | H50: =((ABS($C$42-F50)^2)+(ABS($D$42-G50)^2))^0.5 -> 1.0665178 | I50: =1/H50^$D$40 -> 0.93763083 | K50: =M15/H50^$D$40 -> 0.10232993 | N50: =N15/H50^$D$40 -> 0.028305194
E51: =C16 -> 25025250 | F51: =E16 -> 9.3610278 | G51: =F16 -> -73.593389 | H51: =((ABS($C$42-F51)^2)+(ABS($D$42-G51)^2))^0.5 -> 0.96137078 | I51: =1/H51^$D$40 -> 1.0401814 | K51: =M16/H51^$D$40 -> 0.092471461 | N51: =N16/H51^$D$40 -> 0.033405475
E52: =C17 -> 28010070 | F52: =E17 -> 10.1855 | G52: =F17 -> -73.467111 | H52: =((ABS($C$42-F52)^2)+(ABS($D$42-G52)^2))^0.5 -> 0.5430711 | I52: =1/H52^$D$40 -> 1.8413795 | K52: =M17/H52^$D$40 -> 0.18293055 | N52: =N17/H52^$D$40 -> 0.097100651
E53: =C18 -> 28020080 | F53: =E18 -> 9.8480833 | G53: =F18 -> -73.462194 | H53: =((ABS($C$42-F53)^2)+(ABS($D$42-G53)^2))^0.5 -> 0.56719626 | I53: =1/H53^$D$40 -> 1.7630582 | K53: =M18/H53^$D$40 -> 0.26395404 | N53: =N18/H53^$D$40 -> 0.11320336
E54: =C19 -> 28020150 | F54: =E19 -> 10.029972 | G54: =F19 -> -73.668833 | H54: =((ABS($C$42-F54)^2)+(ABS($D$42-G54)^2))^0.5 -> 0.73186333 | I54: =1/H54^$D$40 -> 1.3663753 | K54: =M19/H54^$D$40 -> 0.1739177 | N54: =N19/H54^$D$40 -> 0.085900722
... E67: =C32 -> 28040350 | F67: =E32 -> 9.6569722 | G67: =F32 -> -73.743694 | H67: =((ABS($C$42-F67)^2)+(ABS($D$42-G67)^2))^0.5 -> 0.9029499 | I67: =1/H67^$D$40 -> 1.1074812 | K67: =M32/H67^$D$40 -> 0.1400989 | N67: =N32/H67^$D$40 -> 0.092376894
...

Sheet Comparacion
B2: Comparación de resultados de los métodos propuestos
B3: Estación | C3: Medio zonal estaciones reales, mm | D3: Método 1 | F3: Método 2 | H3: Método 3 | J3: Método 4
D4: PMax24h, mm | E4: Similitud | F4: PMax24h, mm | G4: Similitud | H4: PMax24h, mm | I4: Similitud | J4: PMax24h, mm | K4: Similitud
B5: Virtual1 | C5: =Metodo1!H5 -> 97.615969 | D5: =+Metodo1!H33 -> 95.90906 | E5: =IF(D5<$C$5,D5/$C$5,$C$5/D5) -> 0.98251404 | F5: =+Metodo2!H33 -> 86.669481 | G5: =IF(F5<$C$5,F5/$C$5,$C$5/F5) -> 0.88786171 | H5: =+Metodo3!H33 -> 4.5526918 | I5: =IF(H5<$C$5,H5/$C$5,$C$5/H5) -> 0.046638802 | J5: =+Metodo4!I33 -> 50.044692 | K5: =IF(J5<$C$5,J5/$C$5,$C$5/J5) -> 0.51266911
B6: Virtual2 | D6: =+Metodo1!H34 -> 96.581282 | E6: =IF(D6<$C$5,D6/$C$5,$C$5/D6) -> 0.98940044 | F6: =+Metodo2!H34 -> 116.88997 | G6: =IF(F6<$C$5,F6/$C$5,$C$5/F6) -> 0.83510988 | H6: =+Metodo3!H34 -> 12.335298 | I6: =IF(H6<$C$5,H6/$C$5,$C$5/H6) -> 0.12636558 | J6: =+Metodo4!I34 -> 73.557817 | K6: =IF(J6<$C$5,J6/$C$5,$C$5/J6) -> 0.75354287
B7: Virtual3 | D7: =+Metodo1!H35 -> 96.555343 | E7: =IF(D7<$C$5,D7/$C$5,$C$5/D7) -> 0.98913471 | F7: =+Metodo2!H35 -> 129.63112 | G7: =IF(F7<$C$5,F7/$C$5,$C$5/F7) -> 0.75302881 | H7: =+Metodo3!H35 -> 31.4461 | I7: =IF(H7<$C$5,H7/$C$5,$C$5/H7) -> 0.32214095 | J7: =+Metodo4!I35 -> 91.52756 | K7: =IF(J7<$C$5,J7/$C$5,$C$5/J7) -> 0.93762897
B8: Virtual4 | D8: =+Metodo1!H36 -> 101.23163 | E8: =IF(D8<$C$5,D8/$C$5,$C$5/D8) -> 0.96428326 | F8: =+Metodo2!H36 -> 111.13931 | G8: =IF(F8<$C$5,F8/$C$5,$C$5/F8) -> 0.87832079 | H8: =+Metodo3!H36 -> 7.4434259 | I8: =IF(H8<$C$5,H8/$C$5,$C$5/H8) -> 0.076252134 | J8: =+Metodo4!I36 -> 64.32826 | K8: =IF(J8<$C$5,J8/$C$5,$C$5/J8) -> 0.65899321

Sheet Metodo2EjemploBasico
B2: Método 2: ejemplo básico de estimación de precipitación máxima en estaciones virtuales.
B3: A partir de la relación entre la precipitación máxima, la precipitación media y el valor inverso de la distancia. (método propuesto por GEAR, 2019)
B5: A. Estaciones
B6: Clase | C6: Código | D6: PMed,mm | E6: PMax24H,mm | F6: R | G6: Función de estimación
B7: Real | C7: P1 | D7: 1200 | E7: 89 | F7: =E7/D7 -> 0.074166667
C8: P2 | D8: 960 | E8: 78 | F8: =E8/D8 -> 0.08125
C9: P3 | D9: 1120 | E9: 96 | F9: =E9/D9 -> 0.085714286
B10: Virtual | C10: PV1 | D10: 1034 | E10: =D10*I16 -> 84.637512 | F10: << Datos virtuales a estimar
C11: PV2 | D11: 785 | E11: =D11*I19 -> 63.773153
B13: B. Matriz de distancias y relaciones
B14: Potencia de tensión, n: | D14: 1 | E14: n = 0, exluye la distancia de la ponderación
B15: Estación virtual a completar | C15: Estación testigo | D15: d, distancia, m | E15: 1/dn, inverso de la distancia | F15: ∑ 1/dn | G15: R / dn | H15: ∑ R/dn | I15: Relación
B16: =C10 -> PV1 | C16: =C7 -> P1 | D16: 7000 | E16: =1/D16^$D$14 -> 0.00014285714 | F16: =SUM(E16:E18) -> 0.00063392857 | G16: =F7/D16^$D$14 -> 1.0595238e-05 | H16: =SUM(G16:G18) -> 5.1889881e-05 | I16: =H16/F16 -> 0.08185446
C17: =C8 -> P2 | D17: 5600 | E17: =1/D17^$D$14 -> 0.00017857143 | G17: =F8/D17^$D$14 -> 1.4508929e-05
C18: =C9 -> P3 | D18: 3200 | E18: =1/D18^$D$14 -> 0.0003125 | G18: =F9/D18^$D$14 -> 2.6785714e-05
B19: =C11 -> PV2 | C19: =C7 -> P1 | D19: 8200 | E19: =1/D19^$D$14 -> 0.00012195122 | F19: =SUM(E19:E21) -> 0.00051425891 | G19: =F7/D19^$D$14 -> 9.0447154e-06 | H19: =SUM(G19:G21) -> 4.1778232e-05 | I19: =H19/F19 -> 0.081239685
C20: =C8 -> P2 | D20: 5000 | E20: =1/D20^$D$14 -> 0.0002 | G20: =F8/D20^$D$14 -> 1.625e-05
C21: =C9 -> P3 | D21: 5200 | E21: =1/D21^$D$14 -> 0.00019230769 | G21: =F9/D21^$D$14 -> 1.6483516e-05

Sheet {R}
B2: Contenido creado por:
B3: r.cfdtools@gmail.com & GEAR
B4: https://github.com/rcfdtools
B6: Licencia, cláusulas y condiciones de uso en:
B7: https://github.com/rcfdtools/R.HydroTools/wiki/License
B22: Password: 1234
